<?xml version="1.0"?>

<robot>
  
    <!-- body of the bot -->
  <link name="base_arm">
    <pose>0 0 0 0 0 0</pose>
    <inertial>
      <mass value="0.01"/>
      <origin rpy="0 0 0" xyz="0 0 0"/>
      <inertia ixx="0.0395416666667" ixy="0" ixz="0" iyy="0.106208333333" iyz="0" izz="0.106208333333"/>
    </inertial>
    <collision name="c">
      <origin rpy="0 0 0" xyz="0 0 0"/>
      <geometry>
        <mesh filename="package://hexbot/meshes/base.dae" scale="0.1 0.1 0.1"/>
      </geometry>
    </collision>
    <visual>
      <origin rpy="0 0 0" xyz="0 0 0"/>
      <geometry>
        <mesh filename="package://hexbot/meshes/base.dae" scale="0.1 0.1 0.1"/>
      </geometry>
      <material name="blue"/>
    </visual>
  </link>

  <joint name="joint_base" type="fixed">
    <origin rpy="0 0 0" xyz="0.0850 0.09 0.15"/>
    <parent link="link_chassis"/>
    <child link="base_arm"/>
  </joint>

  <link name="base_top">
    <pose>0 0 0 0 0 0</pose>
    <inertial>
      <mass value="0.01"/>
      <origin rpy="0 0 0" xyz="0 0 0"/>
      <inertia ixx="0.0395416666667" ixy="0" ixz="0" iyy="0.106208333333" iyz="0" izz="0.106208333333"/>
    </inertial>
    <collision name="ca">
      <origin rpy="0 0 0" xyz="0 0 0"/>
      <geometry>
        <mesh filename="package://hexbot/meshes/base_top.dae" scale="0.1 0.1 0.1"/>
      </geometry>
    </collision>
    <visual>
      <origin rpy="0 0 0" xyz="0 0 0"/>
      <geometry>
        <mesh filename="package://hexbot/meshes/base_top.dae" scale="0.1 0.1 0.1"/>
      </geometry>
      <material name="blue"/>
    </visual>
  </link>

  <joint name="joint_base_top" type="continuous">
    <origin rpy="0 0 0" xyz="0 0 0.048"/>
    <parent link="base_arm"/>
    <child link="base_top"/>
    <axis xyz="0 0 0.048"/>
  </joint>

    <link name="arm_lower">
    <pose>0 0 0 0 0 0</pose>
    <inertial>
      <mass value="0.01"/>
      <origin rpy="0 0 0" xyz="0 0 0"/>
      <inertia ixx="0.0395416666667" ixy="0" ixz="0" iyy="0.106208333333" iyz="0" izz="0.106208333333"/>
    </inertial>
    <collision name="ca">
      <origin rpy="0 0 0" xyz="0 0 0"/>
      <geometry>
        <mesh filename="package://hexbot/meshes/lower_arm.dae" scale="0.1 0.1 0.1"/>
      </geometry>
    </collision>
    <visual>
      <origin rpy="0 0 0" xyz="0 0 0"/>
      <geometry>
        <mesh filename="package://hexbot/meshes/lower_arm.dae" scale="0.1 0.1 0.1"/>
      </geometry>
      <material name="blue"/>
    </visual>
  </link>

  <joint name="joint_arm_lower" type="continuous">
    <origin rpy="0 0 0" xyz="0 0.01 0.045"/>
    <parent link="base_top"/>
    <child link="arm_lower"/>
    <axis xyz="0 0 0.048"/>
  </joint>

  <link name="arm_upper">
    <pose>0 0 0 0 0 0</pose>
    <inertial>
      <mass value="0.01"/>
      <origin rpy="0 0 0" xyz="0 0 0"/>
      <inertia ixx="0.0395416666667" ixy="0" ixz="0" iyy="0.106208333333" iyz="0" izz="0.106208333333"/>
    </inertial>
    <collision name="caf">
      <origin rpy="0 0 0" xyz="0 0 0"/>
      <geometry>
        <mesh filename="package://hexbot/meshes/upper_arm.dae" scale="0.1 0.1 0.1"/>
      </geometry>
    </collision>
    <visual>
      <origin rpy="0 0 0" xyz="0 0 0"/>
      <geometry>
        <mesh filename="package://hexbot/meshes/upper_arm.dae" scale="0.1 0.1 0.1"/>
      </geometry>
      <material name="blue"/>
    </visual>
  </link>

  <joint name="joint_arm_upper" type="continuous">
    <origin rpy="0 0 0" xyz="0 0.01 0.15"/>
    <parent link="arm_lower"/>
    <child link="arm_upper"/>
    <axis xyz="0 0 0.048"/>
  </joint>


</robot>