<?xml version="1.0" encoding="utf-8" ?>
<!-- =================================================================================== -->
<!-- |    This document was autogenerated by xacro from /home/pranavkdas/simulation_ws/src/hexbot/urdf/armmove.xacro | -->
<!-- |    EDITING THIS FILE BY HAND IS NOT RECOMMENDED                                 | -->
<!-- =================================================================================== -->
<robot name="hexbot">
    <!-- body of the bot -->
    <link name="base_arm">
        <pose>0 0 0 0 0 0</pose>
        
<inertial>
            <mass value="0.01" />
            <origin rpy="0 0 0" xyz="0 0 0" />
            <inertia ixx="0.0395416666667" ixy="0" ixz="0" iyy="0.106208333333" iyz="0" izz="0.106208333333" />
        </inertial>

        <collision name="c">
            <origin rpy="0 0 0" xyz="0 0 0" />
            <geometry>
                <mesh filename="package://hexbot/meshes/base.dae" scale="0.1 0.1 0.1" />
            </geometry>
        </collision>
        <visual>
            <origin rpy="0 0 0" xyz="0 0 0" />
            <geometry>
                <mesh filename="package://hexbot/meshes/base.dae" scale="0.1 0.1 0.1" />
            </geometry>
            <material name="blue" />
        </visual>
    </link>
    <link name="base_top">
        <pose>0 0 0 0 0 0</pose>
        
<inertial>
            <mass value="0.01" />
            <origin rpy="0 0 0" xyz="0 0 0" />
            <inertia ixx="0.0395416666667" ixy="0" ixz="0" iyy="0.106208333333" iyz="0" izz="0.106208333333" />
        </inertial>

        <collision name="ca">
            <origin rpy="0 0 0" xyz="0 0 0" />
            <geometry>
                <mesh filename="package://hexbot/meshes/base_top.dae" scale="0.1 0.1 0.1" />
            </geometry>
        </collision>
        <visual>
            <origin rpy="0 0 0" xyz="0 0 0" />
            <geometry>
                <mesh filename="package://hexbot/meshes/base_top.dae" scale="0.1 0.1 0.1" />
            </geometry>
            <material name="blue" />
        </visual>
    </link>
    <joint name="joint_base_top" type="continuous">
        <origin rpy="0 0 0" xyz="0 0 0.048" />
        <parent link="base_arm" />
        <child link="base_top" />
        <axis xyz="0 0 0.048" />
        <limit effort="87" lower="-3.14" upper="3.14" velocity="2.3925" />
    </joint>
    <link name="arm_lower">
        <pose>0 0 0 0 0 0</pose>
        
<inertial>
            <mass value="0.01" />
            <origin rpy="0 0 0" xyz="0 0 0" />
            <inertia ixx="0.0395416666667" ixy="0" ixz="0" iyy="0.106208333333" iyz="0" izz="0.106208333333" />
        </inertial>

        <collision name="ca">
            <origin rpy="0 0 0" xyz="0 0 0" />
            <geometry>
                <mesh filename="package://hexbot/meshes/lower_arm.dae" scale="0.1 0.1 0.1" />
            </geometry>
        </collision>
        <visual>
            <origin rpy="0 0 0" xyz="0 0 0" />
            <geometry>
                <mesh filename="package://hexbot/meshes/lower_arm.dae" scale="0.1 0.1 0.1" />
            </geometry>
            <material name="blue" />
        </visual>
    </link>
    <joint name="joint_arm_lower" type="revolute">
        <origin rpy="0 0 0" xyz="0 0.01 0.045" />
        <parent link="base_top" />
        <child link="arm_lower" />
        <axis xyz="0 0.048 0" />
        <limit effort="87" lower="-1.4" upper="1.7" velocity="2.3925" />
    </joint>
    <link name="arm_upper">
        <pose>0 0 0 0 0 0</pose>
        
<inertial>
            <mass value="0.01" />
            <origin rpy="0 0 0" xyz="0 0 0" />
            <inertia ixx="0.0395416666667" ixy="0" ixz="0" iyy="0.106208333333" iyz="0" izz="0.106208333333" />
        </inertial>

        <collision name="caf">
            <origin rpy="0 0 0" xyz="0 0 0" />
            <geometry>
                <mesh filename="package://hexbot/meshes/upper_arm.dae" scale="0.1 0.1 0.1" />
            </geometry>
        </collision>
        <visual>
            <origin rpy="0 0 0" xyz="0 0 0" />
            <geometry>
                <mesh filename="package://hexbot/meshes/upper_arm.dae" scale="0.1 0.1 0.1" />
            </geometry>
            <material name="blue" />
        </visual>
    </link>
    <joint name="joint_arm_upper" type="revolute">
        <origin rpy="0 0 0" xyz="0 0.01 0.15" />
        <parent link="arm_lower" />
        <child link="arm_upper" />
        <axis xyz="0 0.048 0" />
        <limit effort="87" lower="-2.3" upper="2.3" velocity="2.3925" />
    </joint>
    <link name="lastlink">
        <pose>0 0 0 0 0 0</pose>
        
<inertial>
            <mass value="0.01" />
            <origin rpy="0 0 0" xyz="0 0 0" />
            <inertia ixx="0.0395416666667" ixy="0" ixz="0" iyy="0.106208333333" iyz="0" izz="0.106208333333" />
        </inertial>

        <collision name="caf">
            <origin rpy="0 0 0" xyz="0 0 0" />
            <geometry>
                <box size="0.01 0.1 0.01" />
            </geometry>
        </collision>
        <visual>
            <origin rpy="0 0 0" xyz="0 0 0" />
            <geometry>
                <box size="0.01 0.10 0.01" />
            </geometry>
            <material name="blue" />
        </visual>
    </link>
    <joint name="joint_lastlink" type="revolute">
        <origin rpy="1.5707 0 0" xyz="0 0.01 0.15" />
        <parent link="arm_upper" />
        <child link="lastlink" />
        <axis xyz="0 0 -0.05" />
        <limit effort="87" lower="-2.3" upper="2.3" velocity="2.3925" />
    </joint>
    <link name="hand">
        
<inertial>
            <origin rpy="0 0 0" xyz="0 0 0" />
            <mass value="1" />
            <inertia ixx="0.0010417" ixy="0" ixz="0" iyy="0.00028333" iyz="0" izz="0.0009083" />
        </inertial>

        <visual>
            <origin rpy="0 0 0" xyz="0 0 0" />
            <geometry>
                <box size="0.05 0.01 0.01" />
            </geometry>
            <material name="white" />
        </visual>
        <collision>
            <origin rpy="0 0 0" xyz="0 0 0" />
            <geometry>
                <box size="0.03 0.03 0.02" />
            </geometry>
        </collision>
    </link>
    <joint name="hand_toup" type="fixed">
        <origin rpy="0 0 0" xyz="0 0.055 0" />
        <parent link="lastlink" />
        <child link="hand" />
    </joint>
    <link name="fingerleft">
        
<inertial>
            <origin rpy="0 0 0" xyz="0 0 0" />
            <mass value="1" />
            <inertia ixx="0.0010417" ixy="0" ixz="0" iyy="0.00028333" iyz="0" izz="0.0009083" />
        </inertial>

        <visual>
            <origin rpy="0 0 0" xyz="0 0 0" />
            <geometry>
                <box size="0.01 0.05 0.01" />
            </geometry>
            <material name="white" />
        </visual>
        <collision>
            <origin rpy="0 0 0" xyz="0 0 0" />
            <geometry>
                <box size="0.03 0.03 0.02" />
            </geometry>
        </collision>
    </link>
    <joint name="fing_tohand" type="prismatic">
        <origin rpy="0 0 0" xyz="-0.02 0.028 0" />
        <parent link="hand" />
        <child link="fingerleft" />
        <limit effort="20" lower="0.0" upper="0.04" velocity="0.2" />
    </joint>
    <link name="fingerright">
        
<inertial>
            <origin rpy="0 0 0" xyz="0 0 0" />
            <mass value="1" />
            <inertia ixx="0.0010417" ixy="0" ixz="0" iyy="0.00028333" iyz="0" izz="0.0009083" />
        </inertial>

        <visual>
            <origin rpy="0 0 0" xyz="0 0 0" />
            <geometry>
                <box size="0.01 0.05 0.01" />
            </geometry>
            <material name="white" />
        </visual>
        <collision>
            <origin rpy="0 0 0" xyz="0 0 0" />
            <geometry>
                <box size="0.03 0.03 0.02" />
            </geometry>
        </collision>
    </link>
    <joint name="fingr_tohand" type="prismatic">
        <origin rpy="0 0 0" xyz="0.02 0.028 0" />
        <parent link="hand" />
        <child link="fingerright" />
        <limit effort="20" lower="0.01" upper="0" velocity="0.2" />
    </joint>
    <!--
  <link name="panda_hand">
        <visual>
            <geometry>
                <mesh filename="package://hexbot/meshes/hand.stl" />
            </geometry>
        </visual>
        <collision>
            <geometry>
                <mesh filename="package://hexbot/meshes/hand.stl" />
            </geometry>
        </collision>
    </link>
    <link name="panda_leftfinger">
        <visual>
            <geometry>
                <mesh filename="package://hexbot/meshes/finger.stl" />
            </geometry>
        </visual>
        <collision>
            <geometry>
                <mesh filename="package://hexbot/meshes/finger.stl" />
            </geometry>
        </collision>
    </link>
    <link name="panda_rightfinger">
        <visual>
            <origin rpy="0 0 3.14159265359" xyz="0 0 0" />
            <geometry>
                <mesh filename="package://hexbot/meshes/finger.stl" />
            </geometry>
        </visual>
        <collision>
            <origin rpy="0 0 3.14159265359" xyz="0 0 0" />
            <geometry>
                <mesh filename="package://hexbot/meshes/finger.stl" />
            </geometry>
        </collision>
    </link>
    <joint name="panda_finger_joint1" type="prismatic">
        <parent link="panda_hand" />
        <child link="panda_leftfinger" />
        <origin rpy="0 0 0" xyz="0 0 0.0584" />
        <axis xyz="0 1 0" />
        <limit effort="20" lower="0.0" upper="0.04" velocity="0.2" />
    </joint>
-->
    
<transmission name="trans_joint_base_top">
        <type>transmission_interface/SimpleTransmission</type>
        <joint name="joint_base_top">
            <hardwareInterface>hardware_interface/PositionJointInterface</hardwareInterface>
        </joint>
        <actuator name="joint_base_top_motor">
            <hardwareInterface>hardware_interface/PositionJointInterface</hardwareInterface>
            <mechanicalReduction>1</mechanicalReduction>
        </actuator>
    </transmission>
    <transmission name="trans_joint_arm_lower">
        <type>transmission_interface/SimpleTransmission</type>
        <joint name="joint_arm_lower">
            <hardwareInterface>hardware_interface/PositionJointInterface</hardwareInterface>
        </joint>
        <actuator name="joint_arm_lower_motor">
            <hardwareInterface>hardware_interface/PositionJointInterface</hardwareInterface>
            <mechanicalReduction>1</mechanicalReduction>
        </actuator>
    </transmission>
    <transmission name="trans_joint_arm_upper">
        <type>transmission_interface/SimpleTransmission</type>
        <joint name="joint_arm_upper">
            <hardwareInterface>hardware_interface/PositionJointInterface</hardwareInterface>
        </joint>
        <actuator name="joint_arm_upper_motor">
            <hardwareInterface>hardware_interface/PositionJointInterface</hardwareInterface>
            <mechanicalReduction>1</mechanicalReduction>
        </actuator>
    </transmission>
    <transmission name="trans_joint_lastlink">
        <type>transmission_interface/SimpleTransmission</type>
        <joint name="joint_lastlink">
            <hardwareInterface>hardware_interface/PositionJointInterface</hardwareInterface>
        </joint>
        <actuator name="joint_lastlink_motor">
            <hardwareInterface>hardware_interface/PositionJointInterface</hardwareInterface>
            <mechanicalReduction>1</mechanicalReduction>
        </actuator>
    </transmission>
    <transmission name="trans_fing_tohand">
        <type>transmission_interface/SimpleTransmission</type>
        <joint name="fing_tohand">
            <hardwareInterface>hardware_interface/EffortJointInterface</hardwareInterface>
        </joint>
        <actuator name="fing_tohand_motor">
            <hardwareInterface>hardware_interface/EffortJointInterface</hardwareInterface>
            <mechanicalReduction>1</mechanicalReduction>
        </actuator>
    </transmission>
    <transmission name="trans_fingr_tohand">
        <type>transmission_interface/SimpleTransmission</type>
        <joint name="fingr_tohand">
            <hardwareInterface>hardware_interface/EffortJointInterface</hardwareInterface>
        </joint>
        <actuator name="fingr_tohand_motor">
            <hardwareInterface>hardware_interface/EffortJointInterface</hardwareInterface>
            <mechanicalReduction>1</mechanicalReduction>
        </actuator>
    </transmission>
    <gazebo>
        <plugin name="gazebo_ros_control" filename="libgazebo_ros_control.so">
            <robotNamespace>/</robotNamespace>
        </plugin>
    </gazebo>
</robot>